<?xml version="1.0" encoding="utf-8"?>
<!-- This URDF was automatically created by SolidWorks to URDF Exporter! Originally created by Stephen Brawner (brawner@gmail.com) 
     Commit Version: 1.6.0-1-g15f4949  Build Version: 1.6.7594.29634
     For more information, please see http://wiki.ros.org/sw_urdf_exporter -->
<robot
  name="V000">
  <link
    name="body">
    <inertial>
      <origin
        xyz="-9.5488E-07 0.046412 0.012127"
        rpy="0 0 0" />
      <mass
        value="0.7275" />
      <inertia
        ixx="0.0024737"
        ixy="1.7563E-08"
        ixz="1.3833E-08"
        iyy="0.0024593"
        iyz="-3.5963E-08"
        izz="0.0024831" />
    </inertial>
    <visual>
      <origin
        xyz="0 0 0"
        rpy="0 0 0" />
      <geometry>
        <mesh
          filename="package://V000/meshes/body.STL" />
      </geometry>
      <material
        name="black">
        <color
          rgba="0 0 0 1" />
      </material>
    </visual>
    <collision>
      <origin
        xyz="0 0 0"
        rpy="0 0 0" />
      <geometry>
        <mesh
          filename="package://V000/meshes/body.STL" />
      </geometry>
    </collision>
  </link>
  <link
    name="00">
    <inertial>
      <origin
        xyz="-0.04403 -3.63E-07 0.057725"
        rpy="0 0 0" />
      <mass
        value="0.10385" />
      <inertia
        ixx="7.6261E-05"
        ixy="1.3685E-14"
        ixz="-6.4182E-10"
        iyy="7.581E-05"
        iyz="-6.4182E-10"
        izz="3.2297E-05" />
    </inertial>
    <visual>
      <origin
        xyz="0 0 0"
        rpy="0 0 0" />
      <geometry>
        <mesh
          filename="package://V000/meshes/00.STL" />
      </geometry>
      <material
        name="blue">
        <color
          rgba="0.79216 0.81961 0.93333 1" />
      </material>
    </visual>
    <collision>
      <origin
        xyz="0 0 0"
        rpy="0 0 0" />
      <geometry>
        <mesh
          filename="package://V000/meshes/00.STL" />
      </geometry>
    </collision>
  </link>
  <joint
    name="body_00"
    type="revolute">
    <origin
      xyz="-0.069859 -0.096152 -0.011848"
      rpy="-3.1416 1.3821 0.94248" />
    <parent
      link="body" />
    <child
      link="00" />
    <axis
      xyz="1 0 0" />
    <limit
      lower="-1.0471975512"
      upper="1.0471975512"
      effort="2"
      velocity="0.2094396" />
  </joint>
  <link
    name="01">
    <inertial>
      <origin
        xyz="-1.452E-06 -1.452E-06 0.057726"
        rpy="0 0 0" />
      <mass
        value="0.10385" />
      <inertia
        ixx="6.6794E-05"
        ixy="2.1896E-13"
        ixz="-2.7936E-09"
        iyy="8.5266E-05"
        iyz="-2.7936E-09"
        izz="3.2297E-05" />
    </inertial>
    <visual>
      <origin
        xyz="0 0 0"
        rpy="0 0 0" />
      <geometry>
        <mesh
          filename="package://V000/meshes/01.STL" />
      </geometry>
      <material
        name="black">
        <color
          rgba="0.79216 0.81961 0.93333 1" />
      </material>
    </visual>
    <collision>
      <origin
        xyz="0 0 0"
        rpy="0 0 0" />
      <geometry>
        <mesh
          filename="package://V000/meshes/01.STL" />
      </geometry>
    </collision>
  </link>
  <joint
    name="00_01"
    type="revolute">
    <origin
      xyz="-0.04403 0 0.0812"
      rpy="0 0 1.5708" />
    <parent
      link="00" />
    <child
      link="01" />
    <axis
      xyz="1 0 0" />
    <limit
      lower="-1.0471975512"
      upper="1.0471975512"
      effort="2"
      velocity="0.2094396" />
  </joint>
  <link
    name="02">
    <inertial>
      <origin
        xyz="-2.498E-16 -0.053216 0.053118"
        rpy="0 0 0" />
      <mass
        value="0.14125" />
      <inertia
        ixx="0.00041656"
        ixy="-2.4496E-18"
        ixz="4.4723E-19"
        iyy="5.4419E-05"
        iyz="6.0803E-05"
        izz="0.00039441" />
    </inertial>
    <visual>
      <origin
        xyz="0 0 0"
        rpy="0 0 0" />
      <geometry>
        <mesh
          filename="package://V000/meshes/02.STL" />
      </geometry>
      <material
        name="blue">
        <color
          rgba="0.79216 0.81961 0.93333 1" />
      </material>
    </visual>
    <collision>
      <origin
        xyz="0 0 0"
        rpy="0 0 0" />
      <geometry>
        <mesh
          filename="package://V000/meshes/02.STL" />
      </geometry>
    </collision>
  </link>
  <joint
    name="01_02"
    type="revolute">
    <origin
      xyz="0 0 0.0812"
      rpy="0 0 0" />
    <parent
      link="01" />
    <child
      link="02" />
    <axis
      xyz="1 0 0" />
    <limit
      lower="-1.0471975512"
      upper="1.0471975512"
      effort="2"
      velocity="0.2094396" />
  </joint>
  <link
    name="10">
    <inertial>
      <origin
        xyz="-0.026771 -3.63E-07 0.057725"
        rpy="0 0 0" />
      <mass
        value="0.10385" />
      <inertia
        ixx="7.6261E-05"
        ixy="1.3685E-14"
        ixz="-6.4182E-10"
        iyy="7.581E-05"
        iyz="-6.4182E-10"
        izz="3.2297E-05" />
    </inertial>
    <visual>
      <origin
        xyz="0 0 0"
        rpy="0 0 0" />
      <geometry>
        <mesh
          filename="package://V000/meshes/10.STL" />
      </geometry>
      <material
        name="blue">
        <color
          rgba="0.79216 0.81961 0.93333 1" />
      </material>
    </visual>
    <collision>
      <origin
        xyz="0 0 0"
        rpy="0 0 0" />
      <geometry>
        <mesh
          filename="package://V000/meshes/10.STL" />
      </geometry>
    </collision>
  </link>
  <joint
    name="body_10"
    type="revolute">
    <origin
      xyz="-0.11611 0.037727 0.0051045"
      rpy="-3.1416 1.3821 -0.31416" />
    <parent
      link="body" />
    <child
      link="10" />
    <axis
      xyz="1 0 0" />
    <limit
      lower="-1.0471975512"
      upper="1.0471975512"
      effort="2"
      velocity="0.2094396" />
  </joint>
  <link
    name="11">
    <inertial>
      <origin
        xyz="-1.452E-06 -1.452E-06 0.057726"
        rpy="0 0 0" />
      <mass
        value="0.10385" />
      <inertia
        ixx="6.6794E-05"
        ixy="2.1896E-13"
        ixz="-2.7936E-09"
        iyy="8.5266E-05"
        iyz="-2.7936E-09"
        izz="3.2297E-05" />
    </inertial>
    <visual>
      <origin
        xyz="0 0 0"
        rpy="0 0 0" />
      <geometry>
        <mesh
          filename="package://V000/meshes/11.STL" />
      </geometry>
      <material
        name="black">
        <color
          rgba="0.79216 0.81961 0.93333 1" />
      </material>
    </visual>
    <collision>
      <origin
        xyz="0 0 0"
        rpy="0 0 0" />
      <geometry>
        <mesh
          filename="package://V000/meshes/11.STL" />
      </geometry>
    </collision>
  </link>
  <joint
    name="10_11"
    type="revolute">
    <origin
      xyz="-0.026771 0 0.0812"
      rpy="0 0 1.5708" />
    <parent
      link="10" />
    <child
      link="11" />
    <axis
      xyz="1 0 0" />
    <limit
      lower="-1.0471975512"
      upper="1.0471975512"
      effort="2"
      velocity="0.2094396" />
  </joint>
  <link
    name="12">
    <inertial>
      <origin
        xyz="9.2981E-16 -0.053216 0.053118"
        rpy="0 0 0" />
      <mass
        value="0.14125" />
      <inertia
        ixx="0.00041656"
        ixy="-2.2192E-19"
        ixz="6.0986E-20"
        iyy="5.4419E-05"
        iyz="6.0803E-05"
        izz="0.00039441" />
    </inertial>
    <visual>
      <origin
        xyz="0 0 0"
        rpy="0 0 0" />
      <geometry>
        <mesh
          filename="package://V000/meshes/12.STL" />
      </geometry>
      <material
        name="blue">
        <color
          rgba="0.79216 0.81961 0.93333 1" />
      </material>
    </visual>
    <collision>
      <origin
        xyz="0 0 0"
        rpy="0 0 0" />
      <geometry>
        <mesh
          filename="package://V000/meshes/12.STL" />
      </geometry>
    </collision>
  </link>
  <joint
    name="11_12"
    type="revolute">
    <origin
      xyz="0 0 0.0812"
      rpy="0 0 0" />
    <parent
      link="11" />
    <child
      link="12" />
    <axis
      xyz="1 0 0" />
    <limit
      lower="-1.0471975512"
      upper="1.0471975512"
      effort="2"
      velocity="0.2094396" />
  </joint>
  <link
    name="20">
    <inertial>
      <origin
        xyz="-0.049485 -3.63E-07 0.057725"
        rpy="0 0 0" />
      <mass
        value="0.10385" />
      <inertia
        ixx="7.6261E-05"
        ixy="1.3685E-14"
        ixz="-6.4182E-10"
        iyy="7.581E-05"
        iyz="-6.4182E-10"
        izz="3.2297E-05" />
    </inertial>
    <visual>
      <origin
        xyz="0 0 0"
        rpy="0 0 0" />
      <geometry>
        <mesh
          filename="package://V000/meshes/20.STL" />
      </geometry>
      <material
        name="blue">
        <color
          rgba="0.79216 0.81961 0.93333 1" />
      </material>
    </visual>
    <collision>
      <origin
        xyz="0 0 0"
        rpy="0 0 0" />
      <geometry>
        <mesh
          filename="package://V000/meshes/20.STL" />
      </geometry>
    </collision>
  </link>
  <joint
    name="body_20"
    type="revolute">
    <origin
      xyz="0.11206 0.036411 -0.017207"
      rpy="3.1416 1.3821 -2.8274" />
    <parent
      link="body" />
    <child
      link="20" />
    <axis
      xyz="1 0 0" />
    <limit
      lower="-1.0471975512"
      upper="1.0471975512"
      effort="2"
      velocity="0.2094396" />
  </joint>
  <link
    name="21">
    <inertial>
      <origin
        xyz="-1.452E-06 -1.452E-06 0.057726"
        rpy="0 0 0" />
      <mass
        value="0.10385" />
      <inertia
        ixx="6.6794E-05"
        ixy="2.1896E-13"
        ixz="-2.7936E-09"
        iyy="8.5266E-05"
        iyz="-2.7936E-09"
        izz="3.2297E-05" />
    </inertial>
    <visual>
      <origin
        xyz="0 0 0"
        rpy="0 0 0" />
      <geometry>
        <mesh
          filename="package://V000/meshes/21.STL" />
      </geometry>
      <material
        name="black">
        <color
          rgba="0.79216 0.81961 0.93333 1" />
      </material>
    </visual>
    <collision>
      <origin
        xyz="0 0 0"
        rpy="0 0 0" />
      <geometry>
        <mesh
          filename="package://V000/meshes/21.STL" />
      </geometry>
    </collision>
  </link>
  <joint
    name="20_21"
    type="revolute">
    <origin
      xyz="-0.049485 0 0.0812"
      rpy="0 0 1.5708" />
    <parent
      link="20" />
    <child
      link="21" />
    <axis
      xyz="1 0 0" />
    <limit
      lower="-1.0471975512"
      upper="1.0471975512"
      effort="2"
      velocity="0.2094396" />
  </joint>
  <link
    name="22">
    <inertial>
      <origin
        xyz="-6.9389E-17 -0.053216 0.053118"
        rpy="0 0 0" />
      <mass
        value="0.14125" />
      <inertia
        ixx="0.00041656"
        ixy="-5.2685E-19"
        ixz="1.7618E-19"
        iyy="5.4419E-05"
        iyz="6.0803E-05"
        izz="0.00039441" />
    </inertial>
    <visual>
      <origin
        xyz="0 0 0"
        rpy="0 0 0" />
      <geometry>
        <mesh
          filename="package://V000/meshes/22.STL" />
      </geometry>
      <material
        name="blue">
        <color
          rgba="0.79216 0.81961 0.93333 1" />
      </material>
    </visual>
    <collision>
      <origin
        xyz="0 0 0"
        rpy="0 0 0" />
      <geometry>
        <mesh
          filename="package://V000/meshes/22.STL" />
      </geometry>
    </collision>
  </link>
  <joint
    name="21_22"
    type="revolute">
    <origin
      xyz="0 0 0.0812"
      rpy="0 0 0" />
    <parent
      link="21" />
    <child
      link="22" />
    <axis
      xyz="1 0 0" />
    <limit
      lower="-1.0471975512"
      upper="1.0471975512"
      effort="2"
      velocity="0.2094396" />
  </joint>
  <link
    name="30">
    <inertial>
      <origin
        xyz="-0.056386 -3.63E-07 0.057725"
        rpy="0 0 0" />
      <mass
        value="0.10385" />
      <inertia
        ixx="7.6261E-05"
        ixy="1.3685E-14"
        ixz="-6.4182E-10"
        iyy="7.581E-05"
        iyz="-6.4182E-10"
        izz="3.2297E-05" />
    </inertial>
    <visual>
      <origin
        xyz="0 0 0"
        rpy="0 0 0" />
      <geometry>
        <mesh
          filename="package://V000/meshes/30.STL" />
      </geometry>
      <material
        name="blue">
        <color
          rgba="0.79216 0.81961 0.93333 1" />
      </material>
    </visual>
    <collision>
      <origin
        xyz="0 0 0"
        rpy="0 0 0" />
      <geometry>
        <mesh
          filename="package://V000/meshes/30.STL" />
      </geometry>
    </collision>
  </link>
  <joint
    name="body_30"
    type="revolute">
    <origin
      xyz="0.068496 -0.094277 -0.023985"
      rpy="3.1416 1.3821 2.1991" />
    <parent
      link="body" />
    <child
      link="30" />
    <axis
      xyz="1 0 0" />
    <limit
      lower="-1.0471975512"
      upper="1.0471975512"
      effort="2"
      velocity="0.2094396" />
  </joint>
  <link
    name="31">
    <inertial>
      <origin
        xyz="-1.452E-06 -1.452E-06 0.057726"
        rpy="0 0 0" />
      <mass
        value="0.10385" />
      <inertia
        ixx="6.6794E-05"
        ixy="2.1896E-13"
        ixz="-2.7936E-09"
        iyy="8.5266E-05"
        iyz="-2.7936E-09"
        izz="3.2297E-05" />
    </inertial>
    <visual>
      <origin
        xyz="0 0 0"
        rpy="0 0 0" />
      <geometry>
        <mesh
          filename="package://V000/meshes/31.STL" />
      </geometry>
      <material
        name="black">
        <color
          rgba="0.3 0.3 0.3 1" />
      </material>
    </visual>
    <collision>
      <origin
        xyz="0 0 0"
        rpy="0 0 0" />
      <geometry>
        <mesh
          filename="package://V000/meshes/31.STL" />
      </geometry>
    </collision>
  </link>
  <joint
    name="30_31"
    type="revolute">
    <origin
      xyz="-0.056386 0 0.0812"
      rpy="0 0 1.5708" />
    <parent
      link="30" />
    <child
      link="31" />
    <axis
      xyz="1 0 0" />
    <limit
      lower="-1.0471975512"
      upper="1.0471975512"
      effort="2"
      velocity="0.2094396" />
  </joint>
  <link
    name="32">
    <inertial>
      <origin
        xyz="2.498E-16 -0.053216 0.053118"
        rpy="0 0 0" />
      <mass
        value="0.14125" />
      <inertia
        ixx="0.00041656"
        ixy="1.6941E-20"
        ixz="5.421E-20"
        iyy="5.4419E-05"
        iyz="6.0803E-05"
        izz="0.00039441" />
    </inertial>
    <visual>
      <origin
        xyz="0 0 0"
        rpy="0 0 0" />
      <geometry>
        <mesh
          filename="package://V000/meshes/32.STL" />
      </geometry>
      <material
        name="blue">
        <color
          rgba="0.6078431373 0.8666666667 1 1" />
      </material>
    </visual>
    <collision>
      <origin
        xyz="0 0 0"
        rpy="0 0 0" />
      <geometry>
        <mesh
          filename="package://V000/meshes/32.STL" />
      </geometry>
    </collision>
  </link>
  <joint
    name="31_32"
    type="revolute">
    <origin
      xyz="0 0 0.0812"
      rpy="0 0 0" />
    <parent
      link="31" />
    <child
      link="32" />
    <axis
      xyz="1 0 0" />
    <limit
      lower="-1.0471975512"
      upper="1.0471975512"
      effort="2"
      velocity="0.2094396" />
  </joint>
</robot>